Workbook

Sheet Pengaturan
A1: Pengaturan
A2: Overhead & Profit (%) | B2: 0.1 | C2: Ditambahkan ke jumlah harga bahan+upah di tiap AHSP
A3: PPN (%) | B3: 0.11 | C3: Dipakai di RAB, bukan di HSP
A5: PENTING
A6: Semua harga dasar adalah CONTOH (kira-kira level Jawa 2024). Wajib diganti dengan harga daerah/proyek.
A7: Koefisien berbasis SNI 7394:2008 (tata cara perhitungan harga satuan pekerjaan), ditulis dari ingatan - BELUM dicocokkan baris-per-baris dengan dokumen resmi.
A8: Kolom "Keyakinan": tinggi = angka diyakini sesuai SNI; sedang = cek ulang ke dokumen resmi sebelum dipakai di proyek nyata.
A9: Font biru = input yang boleh diubah (harga, koefisien, persen). Font hitam = formula.

Sheet Harga Dasar
A1: Kode | B1: Jenis | C1: Nama | D1: Satuan | E1: Harga Satuan (Rp)
A2: L.01 | B2: upah | C2: Pekerja | D2: OH | E2: 120000
A3: L.02 | B3: upah | C3: Tukang Batu | D3: OH | E3: 150000
A4: L.03 | B4: upah | C4: Tukang Kayu | D4: OH | E4: 150000
A5: L.04 | B5: upah | C5: Tukang Besi | D5: OH | E5: 150000
A6: L.05 | B6: upah | C6: Tukang Cat | D6: OH | E6: 150000
A7: L.06 | B7: upah | C7: Kepala Tukang | D7: OH | E7: 165000
A8: L.07 | B8: upah | C8: Mandor | D8: OH | E8: 175000
A9: M.01 | B9: bahan | C9: Semen Portland (PC) | D9: kg | E9: 1400
A10: M.02 | B10: bahan | C10: Pasir pasang | D10: m3 | E10: 280000
A11: M.03 | B11: bahan | C11: Pasir urug | D11: m3 | E11: 220000
A12: M.04 | B12: bahan | C12: Bata merah | D12: bh | E12: 900
A13: M.05 | B13: bahan | C13: Batu belah | D13: m3 | E13: 300000
... A29: M.21 | B29: bahan | C29: Semen warna (nat) | D29: kg | E29: 12000

Sheet AHSP
A1: Kode | B1: Uraian Pekerjaan | C1: Satuan | D1: Kode Komp. | E1: Komponen | F1: Sat. | G1: Koefisien | H1: Harga Satuan (Rp) | I1: Jumlah (Rp)
A2: A. Pekerjaan Tanah
A3: A.01 | B3: Galian tanah biasa sedalam s.d. 1 m | C3: m3
D4: L.01 | E4: =INDEX('Harga Dasar'!$C$2:$C$29,MATCH(D4,'Harga Dasar'!$A$2:$A$29,0)) -> Pekerja | F4: =INDEX('Harga Dasar'!$D$2:$D$29,MATCH(D4,'Harga Dasar'!$A$2:$A$29,0)) -> OH | G4: 0.75 | H4: =INDEX('Harga Dasar'!$E$2:$E$29,MATCH(D4,'Harga Dasar'!$A$2:$A$29,0)) -> 120000 | I4: =G4*H4 -> 90000
D5: L.07 | E5: =INDEX('Harga Dasar'!$C$2:$C$29,MATCH(D5,'Harga Dasar'!$A$2:$A$29,0)) -> Mandor | F5: =INDEX('Harga Dasar'!$D$2:$D$29,MATCH(D5,'Harga Dasar'!$A$2:$A$29,0)) -> OH | G5: 0.025 | H5: =INDEX('Harga Dasar'!$E$2:$E$29,MATCH(D5,'Harga Dasar'!$A$2:$A$29,0)) -> 175000 | I5: =G5*H5 -> 4375
E6: Jumlah harga bahan + upah | I6: =SUM(I4:I5) -> 94375
E7: Overhead & profit | G7: =Pengaturan!$B$2 -> 0.1 | I7: =I6*G7 -> 9437.5
E8: Harga satuan pekerjaan per m3 | I8: =I6+I7 -> 103812.5
A10: A.02 | B10: Urugan pasir | C10: m3
D11: M.03 | E11: =INDEX('Harga Dasar'!$C$2:$C$29,MATCH(D11,'Harga Dasar'!$A$2:$A$29,0)) -> Pasir urug | F11: =INDEX('Harga Dasar'!$D$2:$D$29,MATCH(D11,'Harga Dasar'!$A$2:$A$29,0)) -> m3 | G11: 1.2 | H11: =INDEX('Harga Dasar'!$E$2:$E$29,MATCH(D11,'Harga Dasar'!$A$2:$A$29,0)) -> 220000 | I11: =G11*H11 -> 264000
D12: L.01 | E12: =INDEX('Harga Dasar'!$C$2:$C$29,MATCH(D12,'Harga Dasar'!$A$2:$A$29,0)) -> Pekerja | F12: =INDEX('Harga Dasar'!$D$2:$D$29,MATCH(D12,'Harga Dasar'!$A$2:$A$29,0)) -> OH | G12: 0.3 | H12: =INDEX('Harga Dasar'!$E$2:$E$29,MATCH(D12,'Harga Dasar'!$A$2:$A$29,0)) -> 120000 | I12: =G12*H12 -> 36000
D13: L.07 | E13: =INDEX('Harga Dasar'!$C$2:$C$29,MATCH(D13,'Harga Dasar'!$A$2:$A$29,0)) -> Mandor | F13: =INDEX('Harga Dasar'!$D$2:$D$29,MATCH(D13,'Harga Dasar'!$A$2:$A$29,0)) -> OH | G13: 0.01 | H13: =INDEX('Harga Dasar'!$E$2:$E$29,MATCH(D13,'Harga Dasar'!$A$2:$A$29,0)) -> 175000 | I13: =G13*H13 -> 1750
E14: Jumlah harga bahan + upah | I14: =SUM(I11:I13) -> 301750
E15: Overhead & profit | G15: =Pengaturan!$B$2 -> 0.1 | I15: =I14*G15 -> 30175
E16: Harga satuan pekerjaan per m3 | I16: =I14+I15 -> 331925
A18: B. Pekerjaan Pondasi
A19: B.01 | B19: Pondasi batu belah, campuran 1 PC : 5 PS | C19: m3
D20: M.05 | E20: =INDEX('Harga Dasar'!$C$2:$C$29,MATCH(D20,'Harga Dasar'!$A$2:$A$29,0)) -> Batu belah | F20: =INDEX('Harga Dasar'!$D$2:$D$29,MATCH(D20,'Harga Dasar'!$A$2:$A$29,0)) -> m3 | G20: 1.2 | H20: =INDEX('Harga Dasar'!$E$2:$E$29,MATCH(D20,'Harga Dasar'!$A$2:$A$29,0)) -> 300000 | I20: =G20*H20 -> 360000
D21: M.01 | E21: =INDEX('Harga Dasar'!$C$2:$C$29,MATCH(D21,'Harga Dasar'!$A$2:$A$29,0)) -> Semen Portland (PC) | F21: =INDEX('Harga Dasar'!$D$2:$D$29,MATCH(D21,'Harga Dasar'!$A$2:$A$29,0)) -> kg | G21: 163 | H21: =INDEX('Harga Dasar'!$E$2:$E$29,MATCH(D21,'Harga Dasar'!$A$2:$A$29,0)) -> 1400 | I21: =G21*H21 -> 228200
D22: M.02 | E22: =INDEX('Harga Dasar'!$C$2:$C$29,MATCH(D22,'Harga Dasar'!$A$2:$A$29,0)) -> Pasir pasang | F22: =INDEX('Harga Dasar'!$D$2:$D$29,MATCH(D22,'Harga Dasar'!$A$2:$A$29,0)) -> m3 | G22: 0.52 | H22: =INDEX('Harga Dasar'!$E$2:$E$29,MATCH(D22,'Harga Dasar'!$A$2:$A$29,0)) -> 280000 | I22: =G22*H22 -> 145600
D23: L.01 | E23: =INDEX('Harga Dasar'!$C$2:$C$29,MATCH(D23,'Harga Dasar'!$A$2:$A$29,0)) -> Pekerja | F23: =INDEX('Harga Dasar'!$D$2:$D$29,MATCH(D23,'Harga Dasar'!$A$2:$A$29,0)) -> OH | G23: 1.5 | H23: =INDEX('Harga Dasar'!$E$2:$E$29,MATCH(D23,'Harga Dasar'!$A$2:$A$29,0)) -> 120000 | I23: =G23*H23 -> 180000
D24: L.02 | E24: =INDEX('Harga Dasar'!$C$2:$C$29,MATCH(D24,'Harga Dasar'!$A$2:$A$29,0)) -> Tukang Batu | F24: =INDEX('Harga Dasar'!$D$2:$D$29,MATCH(D24,'Harga Dasar'!$A$2:$A$29,0)) -> OH | G24: 0.75 | H24: =INDEX('Harga Dasar'!$E$2:$E$29,MATCH(D24,'Harga Dasar'!$A$2:$A$29,0)) -> 150000 | I24: =G24*H24 -> 112500
D25: L.06 | E25: =INDEX('Harga Dasar'!$C$2:$C$29,MATCH(D25,'Harga Dasar'!$A$2:$A$29,0)) -> Kepala Tukang | F25: =INDEX('Harga Dasar'!$D$2:$D$29,MATCH(D25,'Harga Dasar'!$A$2:$A$29,0)) -> OH | G25: 0.075 | H25: =INDEX('Harga Dasar'!$E$2:$E$29,MATCH(D25,'Harga Dasar'!$A$2:$A$29,0)) -> 165000 | I25: =G25*H25 -> 12375
D26: L.07 | E26: =INDEX('Harga Dasar'!$C$2:$C$29,MATCH(D26,'Harga Dasar'!$A$2:$A$29,0)) -> Mandor | F26: =INDEX('Harga Dasar'!$D$2:$D$29,MATCH(D26,'Harga Dasar'!$A$2:$A$29,0)) -> OH | G26: 0.075 | H26: =INDEX('Harga Dasar'!$E$2:$E$29,MATCH(D26,'Harga Dasar'!$A$2:$A$29,0)) -> 175000 | I26: =G26*H26 -> 13125
E27: Jumlah harga bahan + upah | I27: =SUM(I20:I26) -> 1051800
E28: Overhead & profit | G28: =Pengaturan!$B$2 -> 0.1 | I28: =I27*G28 -> 105180
E29: Harga satuan pekerjaan per m3 | I29: =I27+I28 -> 1156980
A31: B.02 | B31: Pondasi batu belah, campuran 1 PC : 4 PS | C31: m3
D32: M.05 | E32: =INDEX('Harga Dasar'!$C$2:$C$29,MATCH(D32,'Harga Dasar'!$A$2:$A$29,0)) -> Batu belah | F32: =INDEX('Harga Dasar'!$D$2:$D$29,MATCH(D32,'Harga Dasar'!$A$2:$A$29,0)) -> m3 | G32: 1.2 | H32: =INDEX('Harga Dasar'!$E$2:$E$29,MATCH(D32,'Harga Dasar'!$A$2:$A$29,0)) -> 300000 | I32: =G32*H32 -> 360000
D33: M.01 | E33: =INDEX('Harga Dasar'!$C$2:$C$29,MATCH(D33,'Harga Dasar'!$A$2:$A$29,0)) -> Semen Portland (PC) | F33: =INDEX('Harga Dasar'!$D$2:$D$29,MATCH(D33,'Harga Dasar'!$A$2:$A$29,0)) -> kg | G33: 202 | H33: =INDEX('Harga Dasar'!$E$2:$E$29,MATCH(D33,'Harga Dasar'!$A$2:$A$29,0)) -> 1400 | I33: =G33*H33 -> 282800
D34: M.02 | E34: =INDEX('Harga Dasar'!$C$2:$C$29,MATCH(D34,'Harga Dasar'!$A$2:$A$29,0)) -> Pasir pasang | F34: =INDEX('Harga Dasar'!$D$2:$D$29,MATCH(D34,'Harga Dasar'!$A$2:$A$29,0)) -> m3 | G34: 0.485 | H34: =INDEX('Harga Dasar'!$E$2:$E$29,MATCH(D34,'Harga Dasar'!$A$2:$A$29,0)) -> 280000 | I34: =G34*H34 -> 135800
D35: L.01 | E35: =INDEX('Harga Dasar'!$C$2:$C$29,MATCH(D35,'Harga Dasar'!$A$2:$A$29,0)) -> Pekerja | F35: =INDEX('Harga Dasar'!$D$2:$D$29,MATCH(D35,'Harga Dasar'!$A$2:$A$29,0)) -> OH | G35: 1.5 | H35: =INDEX('Harga Dasar'!$E$2:$E$29,MATCH(D35,'Harga Dasar'!$A$2:$A$29,0)) -> 120000 | I35: =G35*H35 -> 180000
D36: L.02 | E36: =INDEX('Harga Dasar'!$C$2:$C$29,MATCH(D36,'Harga Dasar'!$A$2:$A$29,0)) -> Tukang Batu | F36: =INDEX('Harga Dasar'!$D$2:$D$29,MATCH(D36,'Harga Dasar'!$A$2:$A$29,0)) -> OH | G36: 0.75 | H36: =INDEX('Harga Dasar'!$E$2:$E$29,MATCH(D36,'Harga Dasar'!$A$2:$A$29,0)) -> 150000 | I36: =G36*H36 -> 112500
D37: L.06 | E37: =INDEX('Harga Dasar'!$C$2:$C$29,MATCH(D37,'Harga Dasar'!$A$2:$A$29,0)) -> Kepala Tukang | F37: =INDEX('Harga Dasar'!$D$2:$D$29,MATCH(D37,'Harga Dasar'!$A$2:$A$29,0)) -> OH | G37: 0.075 | H37: =INDEX('Harga Dasar'!$E$2:$E$29,MATCH(D37,'Harga Dasar'!$A$2:$A$29,0)) -> 165000 | I37: =G37*H37 -> 12375
D38: L.07 | E38: =INDEX('Harga Dasar'!$C$2:$C$29,MATCH(D38,'Harga Dasar'!$A$2:$A$29,0)) -> Mandor | F38: =INDEX('Harga Dasar'!$D$2:$D$29,MATCH(D38,'Harga Dasar'!$A$2:$A$29,0)) -> OH | G38: 0.075 | H38: =INDEX('Harga Dasar'!$E$2:$E$29,MATCH(D38,'Harga Dasar'!$A$2:$A$29,0)) -> 175000 | I38: =G38*H38 -> 13125
E39: Jumlah harga bahan + upah | I39: =SUM(I32:I38) -> 1096600
E40: Overhead & profit | G40: =Pengaturan!$B$2 -> 0.1 | I40: =I39*G40 -> 109660
E41: Harga satuan pekerjaan per m3 | I41: =I39+I40 -> 1206260
A43: C. Pekerjaan Beton
A44: C.01 | B44: Beton K-175 (site mix) | C44: m3
...

Sheet Rekap HSP
A1: Kode | B1: Divisi | C1: Uraian Pekerjaan | D1: Satuan | E1: Bahan (Rp) | F1: Upah (Rp) | G1: Overhead & Profit | H1: Harga Satuan (Rp) | I1: Keyakinan
A2: A.01 | B2: A. Pekerjaan Tanah | C2: Galian tanah biasa sedalam s.d. 1 m | D2: m3 | E2: =SUMPRODUCT((LEFT(AHSP!$D$4:$D$5,1)="M")*AHSP!$I$4:$I$5) -> 0 | F2: =SUMPRODUCT((LEFT(AHSP!$D$4:$D$5,1)="L")*AHSP!$I$4:$I$5) -> 94375 | G2: =AHSP!I7 -> 9437.5 | H2: =AHSP!I8 -> 103812.5 | I2: tinggi
A3: A.02 | B3: A. Pekerjaan Tanah | C3: Urugan pasir | D3: m3 | E3: =SUMPRODUCT((LEFT(AHSP!$D$11:$D$13,1)="M")*AHSP!$I$11:$I$13) -> 264000 | F3: =SUMPRODUCT((LEFT(AHSP!$D$11:$D$13,1)="L")*AHSP!$I$11:$I$13) -> 37750 | G3: =AHSP!I15 -> 30175 | H3: =AHSP!I16 -> 331925 | I3: tinggi
A4: B.01 | B4: B. Pekerjaan Pondasi | C4: Pondasi batu belah, campuran 1 PC : 5 PS | D4: m3 | E4: =SUMPRODUCT((LEFT(AHSP!$D$20:$D$26,1)="M")*AHSP!$I$20:$I$26) -> 733800 | F4: =SUMPRODUCT((LEFT(AHSP!$D$20:$D$26,1)="L")*AHSP!$I$20:$I$26) -> 318000 | G4: =AHSP!I28 -> 105180 | H4: =AHSP!I29 -> 1156980 | I4: tinggi
A5: B.02 | B5: B. Pekerjaan Pondasi | C5: Pondasi batu belah, campuran 1 PC : 4 PS | D5: m3 | E5: =SUMPRODUCT((LEFT(AHSP!$D$32:$D$38,1)="M")*AHSP!$I$32:$I$38) -> 778600 | F5: =SUMPRODUCT((LEFT(AHSP!$D$32:$D$38,1)="L")*AHSP!$I$32:$I$38) -> 318000 | G5: =AHSP!I40 -> 109660 | H5: =AHSP!I41 -> 1206260 | I5: tinggi
A6: C.01 | B6: C. Pekerjaan Beton | C6: Beton K-175 (site mix) | D6: m3 | E6: =SUMPRODUCT((LEFT(AHSP!$D$45:$D$52,1)="M")*AHSP!$I$45:$I$52) -> 861810 | F6: =SUMPRODUCT((LEFT(AHSP!$D$45:$D$52,1)="L")*AHSP!$I$45:$I$52) -> 258395 | G6: =AHSP!I54 -> 112020.5 | H6: =AHSP!I55 -> 1232225.5 | I6: tinggi
A7: C.02 | B7: C. Pekerjaan Beton | C7: Beton K-225 (site mix) | D7: m3 | E7: =SUMPRODUCT((LEFT(AHSP!$D$58:$D$65,1)="M")*AHSP!$I$58:$I$65) -> 916730 | F7: =SUMPRODUCT((LEFT(AHSP!$D$58:$D$65,1)="L")*AHSP!$I$58:$I$65) -> 258395 | G7: =AHSP!I67 -> 117512.5 | H7: =AHSP!I68 -> 1292637.5 | I7: tinggi
A8: C.03 | B8: C. Pekerjaan Beton | C8: Beton K-250 (site mix) | D8: m3 | E8: =SUMPRODUCT((LEFT(AHSP!$D$71:$D$78,1)="M")*AHSP!$I$71:$I$78) -> 931810 | F8: =SUMPRODUCT((LEFT(AHSP!$D$71:$D$78,1)="L")*AHSP!$I$71:$I$78) -> 258395 | G8: =AHSP!I80 -> 119020.5 | H8: =AHSP!I81 -> 1309225.5 | I8: tinggi
A9: C.04 | B9: C. Pekerjaan Beton | C9: Beton K-300 (site mix) | D9: m3 | E9: =SUMPRODUCT((LEFT(AHSP!$D$84:$D$91,1)="M")*AHSP!$I$84:$I$91) -> 965890 | F9: =SUMPRODUCT((LEFT(AHSP!$D$84:$D$91,1)="L")*AHSP!$I$84:$I$91) -> 258395 | G9: =AHSP!I93 -> 122428.5 | H9: =AHSP!I94 -> 1346713.5 | I9: tinggi
A10: C.05 | B10: C. Pekerjaan Beton | C10: Pembesian dengan besi polos/ulir (per 10 kg) | D10: 10 kg | E10: =SUMPRODUCT((LEFT(AHSP!$D$97:$D$102,1)="M")*AHSP!$I$97:$I$102) -> 155550 | F10: =SUMPRODUCT((LEFT(AHSP!$D$97:$D$102,1)="L")*AHSP!$I$97:$I$102) -> 20755 | G10: =AHSP!I104 -> 17630.5 | H10: =AHSP!I105 -> 193935.5 | I10: tinggi
A11: C.06 | B11: C. Pekerjaan Beton | C11: Bekisting kolom (kayu + plywood) | D11: m2 | E11: =SUMPRODUCT((LEFT(AHSP!$D$108:$D$117,1)="M")*AHSP!$I$108:$I$117) -> 303000 | F11: =SUMPRODUCT((LEFT(AHSP!$D$108:$D$117,1)="L")*AHSP!$I$108:$I$117) -> 110240 | G11: =AHSP!I119 -> 41324 | H11: =AHSP!I120 -> 454564 | I11: sedang
A12: D.01 | B12: D. Pekerjaan Dinding | C12: Pasangan dinding bata merah 1/2 bata, campuran 1 PC : 4 PS | D12: m2 | E12: =SUMPRODUCT((LEFT(AHSP!$D$124:$D$130,1)="M")*AHSP!$I$124:$I$130) -> 91140 | F12: =SUMPRODUCT((LEFT(AHSP!$D$124:$D$130,1)="L")*AHSP!$I$124:$I$130) -> 55275 | G12: =AHSP!I132 -> 14641.5 | H12: =AHSP!I133 -> 161056.5 | I12: tinggi
A13: D.02 | B13: D. Pekerjaan Dinding | C13: Plesteran 1 PC : 4 PS, tebal 15 mm | D13: m2 | E13: =SUMPRODUCT((LEFT(AHSP!$D$136:$D$141,1)="M")*AHSP!$I$136:$I$141) -> 15456 | F13: =SUMPRODUCT((LEFT(AHSP!$D$136:$D$141,1)="L")*AHSP!$I$136:$I$141) -> 63600 | G13: =AHSP!I143 -> 7905.6 | H13: =AHSP!I144 -> 86961.6 | I13: tinggi
A14: D.03 | B14: D. Pekerjaan Dinding | C14: Acian | D14: m2 | E14: =SUMPRODUCT((LEFT(AHSP!$D$147:$D$151,1)="M")*AHSP!$I$147:$I$151) -> 4550 | F14: =SUMPRODUCT((LEFT(AHSP!$D$147:$D$151,1)="L")*AHSP!$I$147:$I$151) -> 42400 | G14: =AHSP!I153 -> 4695 | H14: =AHSP!I154 -> 51645 | I14: tinggi
A15: E.01 | B15: E. Pekerjaan Finishing | C15: Pengecatan tembok baru (1 plamir, 1 cat dasar, 2 cat penutup) | D15: m2 | E15: =SUMPRODUCT((LEFT(AHSP!$D$158:$D$164,1)="M")*AHSP!$I$158:$I$164) -> 17700 | F15: =SUMPRODUCT((LEFT(AHSP!$D$158:$D$164,1)="L")*AHSP!$I$158:$I$164) -> 13365 | G15: =AHSP!I166 -> 3106.5 | H15: =AHSP!I167 -> 34171.5 | I15: sedang
A16: E.02 | B16: E. Pekerjaan Finishing | C16: Pasang lantai keramik 20x20 (spesi + nat) | D16: m2 | E16: =SUMPRODUCT((LEFT(AHSP!$D$170:$D$177,1)="M")*AHSP!$I$170:$I$177) -> 88600 | F16: =SUMPRODUCT((LEFT(AHSP!$D$170:$D$177,1)="L")*AHSP!$I$170:$I$177) -> 148400 | G16: =AHSP!I179 -> 23700 | H16: =AHSP!I180 -> 260700 | I16: sedang
